
  You can now view your Streamlit app in your browser.

  Local URL: http://localhost:8502
  Network URL: http://192.168.1.32:8502

2025-03-21 19:11:01.404 Uncaught app exception
Traceback (most recent call last):
  File "/opt/anaconda3/lib/python3.12/site-packages/streamlit/elements/image.py", line 381, in image_to_url
    with open(image, "rb") as f:
         ^^^^^^^^^^^^^^^^^
FileNotFoundError: [Errno 2] No such file or directory: 'COBRAD_figures/topomaps_p_values_vs_controls/LBD_Cognitive_fluctuation/p_values_alpha_power_topomap.png'

During handling of the above exception, another exception occurred:

Traceback (most recent call last):
  File "/opt/anaconda3/lib/python3.12/site-packages/streamlit/runtime/memory_media_file_storage.py", line 164, in _read_file
    with open(filename, "rb") as f:
         ^^^^^^^^^^^^^^^^^^^^
FileNotFoundError: [Errno 2] No such file or directory: 'COBRAD_figures/topomaps_p_values_vs_controls/LBD_Cognitive_fluctuation/p_values_alpha_power_topomap.png'

The above exception was the direct cause of the following exception:

Traceback (most recent call last):
  File "/opt/anaconda3/lib/python3.12/site-packages/streamlit/runtime/scriptrunner/script_runner.py", line 542, in _run_script
    exec(code, module.__dict__)
  File "/Users/nircafri/Desktop/Scripts/Nir/cobrad/4_streamlit_view.py", line 119, in <module>
    st.image(figure_path, caption=figure_file, use_column_width=True)
  File "/opt/anaconda3/lib/python3.12/site-packages/streamlit/runtime/metrics_util.py", line 397, in wrapped_func
    result = non_optional_func(*args, **kwargs)
             ^^^^^^^^^^^^^^^^^^^^^^^^^^^^^^^^^^
  File "/opt/anaconda3/lib/python3.12/site-packages/streamlit/elements/image.py", line 161, in image
    marshall_images(
  File "/opt/anaconda3/lib/python3.12/site-packages/streamlit/elements/image.py", line 544, in marshall_images
    proto_img.url = image_to_url(
                    ^^^^^^^^^^^^^
  File "/opt/anaconda3/lib/python3.12/site-packages/streamlit/elements/image.py", line 393, in image_to_url
    url = runtime.get_instance().media_file_mgr.add(image, mimetype, image_id)
          ^^^^^^^^^^^^^^^^^^^^^^^^^^^^^^^^^^^^^^^^^^^^^^^^^^^^^^^^^^^^^^^^^^^^
  File "/opt/anaconda3/lib/python3.12/site-packages/streamlit/runtime/media_file_manager.py", line 224, in add
    file_id = self._storage.load_and_get_id(
              ^^^^^^^^^^^^^^^^^^^^^^^^^^^^^^
  File "/opt/anaconda3/lib/python3.12/site-packages/streamlit/runtime/memory_media_file_storage.py", line 115, in load_and_get_id
    file_data = self._read_file(path_or_data)
                ^^^^^^^^^^^^^^^^^^^^^^^^^^^^^
  File "/opt/anaconda3/lib/python3.12/site-packages/streamlit/runtime/memory_media_file_storage.py", line 167, in _read_file
    raise MediaFileStorageError(f"Error opening '{filename}'") from ex
streamlit.runtime.media_file_storage.MediaFileStorageError: Error opening 'COBRAD_figures/topomaps_p_values_vs_controls/LBD_Cognitive_fluctuation/p_values_alpha_power_topomap.png'
